<?xml version="1.0" ?>
<robot name="robot_arm" xmlns:xacro="http://www.ros.org/wiki/xacro">

<xacro:include filename="$(find my_arm_description)/urdf/materials.xacro" />
<xacro:include filename="$(find my_arm_description)/urdf/robot_arm.trans" />
<xacro:include filename="$(find my_arm_description)/urdf/robot_arm.gazebo" />

<link name="world"></link>

<joint name="base_fixed_joint" type="fixed">
    <parent link="world"/>
    <child link="base_link"/>
    <origin xyz="0 0 0.2" rpy="0 0 0"/>
</joint>

<link name="base_link">
  <inertial>
    <origin xyz="-0.0019226671084236508 0.03127199959893212 0.003074002176362074" rpy="0 0 0"/>
    <mass value="0.1"/>
    <inertia ixx="0.0135" ixy="0.0" ixz="0.0" iyy="0.0135" iyz="0.0" izz="0.05"/>
  </inertial>
  <visual>
    <origin xyz="0 0 0" rpy="1.57 0 0"/>
    <geometry>
      <mesh filename="package://my_arm_description/meshes/base_link.stl" scale="0.001 0.001 0.001"/>
    </geometry>
    <material name="blue"/>
  </visual>
  <collision>
    <origin xyz="0 0 0" rpy="1.57 0 0"/>
    <geometry>
      <mesh filename="package://my_arm_description/meshes/base_link.stl" scale="0.001 0.001 0.001"/>
    </geometry>
  </collision>
</link>

<link name="Link1_1">
  <inertial>
    <origin xyz="-4.991869489348773e-06 0.01780900870871517 0.005735315172792203" rpy="0 0 0"/>
    <mass value="0.08948947756149551"/>
    <inertia ixx="0.000574" iyy="0.002344" izz="0.002106" ixy="-1.2e-05" iyz="-7.9e-05" ixz="-2e-05"/>
  </inertial>
  <visual>
    <origin xyz="0.002688 -0.06295 -0.001684" rpy="0 0 0"/>
    <geometry>
      <mesh filename="package://my_arm_description/meshes/Link1_1.stl" scale="0.001 0.001 0.001"/>
    </geometry>
    <material name="silver"/>
  </visual>
  <collision>
    <origin xyz="0.002688 -0.06295 -0.001684" rpy="0 0 0"/>
    <geometry>
      <mesh filename="package://my_arm_description/meshes/Link1_1.stl" scale="0.001 0.001 0.001"/>
    </geometry>
  </collision>
</link>

<link name="Link2_1">
  <inertial>
    <origin xyz="0.025500212363618904 0.050000197846483144 2.9486110807164234e-07" rpy="0 0 0"/>
    <mass value="0.01268747558623512"/>
    <inertia ixx="0.000111" iyy="7.8e-05" izz="0.000176" ixy="0.0" iyz="-0.0" ixz="-0.0"/>
  </inertial>
  <visual>
    <origin xyz="0.028738 -0.084331 -0.001684" rpy="0 0 0"/>
    <geometry>
      <mesh filename="package://my_arm_description/meshes/Link2_1.stl" scale="0.001 0.001 0.001"/>
    </geometry>
    <material name="silver"/>
  </visual>
  <collision>
    <origin xyz="0.028738 -0.084331 -0.001684" rpy="0 0 0"/>
    <geometry>
      <mesh filename="package://my_arm_description/meshes/Link2_1.stl" scale="0.001 0.001 0.001"/>
    </geometry>
  </collision>
</link>

<link name="Link3_1">
  <inertial>
    <origin xyz="0.027076002474259824 0.019409440802769573 0.002368883434935072" rpy="0 0 0"/>
    <mass value="0.03877413615001566"/>
    <inertia ixx="0.00025" iyy="0.000103" izz="0.00031" ixy="1e-05" iyz="-7e-06" ixz="0.0"/>
  </inertial>
  <visual>
    <origin xyz="0.028738 -0.184331 -0.001684" rpy="0 0 0"/>
    <geometry>
      <mesh filename="package://my_arm_description/meshes/Link3_1.stl" scale="0.001 0.001 0.001"/>
    </geometry>
    <material name="silver"/>
  </visual>
  <collision>
    <origin xyz="0.028738 -0.184331 -0.001684" rpy="0 0 0"/>
    <geometry>
      <mesh filename="package://my_arm_description/meshes/Link3_1.stl" scale="0.001 0.001 0.001"/>
    </geometry>
  </collision>
</link>

<link name="Link4_1">
  <inertial>
    <origin xyz="0.02792782389157162 0.0015768795382742895 -0.009656526599892783" rpy="0 0 0"/>
    <mass value="0.030477625056794005"/>
    <inertia ixx="6.9e-05" iyy="9.7e-05" izz="5.9e-05" ixy="-1e-06" iyz="0.0" ixz="2e-06"/>
  </inertial>
  <visual>
    <origin xyz="0.030288 -0.27563 -0.005184" rpy="0 0 0"/>
    <geometry>
      <mesh filename="package://my_arm_description/meshes/Link4_1.stl" scale="0.001 0.001 0.001"/>
    </geometry>
    <material name="silver"/>
  </visual>
  <collision>
    <origin xyz="0.030288 -0.27563 -0.005184" rpy="0 0 0"/>
    <geometry>
      <mesh filename="package://my_arm_description/meshes/Link4_1.stl" scale="0.001 0.001 0.001"/>
    </geometry>
  </collision>
</link>

<link name="Link5_1">
  <inertial>
    <origin xyz="0.02792782389157162 0.0015768795382742895 -0.009656526599892783" rpy="0 0 0"/>
    <mass value="0.030477625056794005"/>
    <inertia ixx="6.9e-05" iyy="9.7e-05" izz="5.9e-05" ixy="-1e-06" iyz="0.0" ixz="2e-06"/>
  </inertial>
  <visual>
    <origin xyz="0.030288 -0.27563 -0.005184" rpy="0 0 0"/>
    <geometry>
      <mesh filename="package://my_arm_description/meshes/Link4_1.stl" scale="0.001 0.001 0.001"/>
    </geometry>
    <material name="silver"/>
  </visual>
  <collision>
    <origin xyz="0.030288 -0.27563 -0.005184" rpy="0 0 0"/>
    <geometry>
      <mesh filename="package://my_arm_description/meshes/Link4_1.stl" scale="0.001 0.001 0.001"/>
    </geometry>
  </collision>
</link>

<joint name="joint_1" type="revolute">
  <origin xyz="0 0 0.06" rpy="1.57 0 0"/>
  <parent link="base_link"/>
  <child link="Link1_1"/>
  <axis xyz="0 1 0"/>
  <limit lower="0.0" upper="3.14" effort="5.0" velocity="1.57" />
  <!-- <dynamics damping="0.5" friction="1.0"/> -->
</joint>

<joint name="joint_2" type="revolute">
  <origin xyz="-0.02605 0.021381 0.0" rpy="-1.57 0 0"/>
  <parent link="Link1_1"/>
  <child link="Link2_1"/>
  <axis xyz="1 0 0"/>
  <limit lower="0.0" upper="3.14" effort="5.0" velocity="1.57" />
  <!-- <dynamics damping="0.5" friction="1.0"/> -->
</joint>

<joint name="joint_3" type="revolute">
  <origin xyz="0.0 0.1 0.0" rpy="3.14 0 0"/>
  <parent link="Link2_1"/>
  <child link="Link3_1"/>
  <axis xyz="1 0 0"/>
  <limit lower="0.52" upper="3.14" effort="5.0" velocity="1.57" />
  <!-- <dynamics damping="0.5" friction="1.0"/> -->
</joint>

<joint name="joint_4" type="revolute">
  <origin xyz="-0.00155 0.091299 0.0035" rpy="-1.57 0 0"/>
  <parent link="Link3_1"/>
  <child link="Link4_1"/>
  <axis xyz="1 0 0"/>
  <limit lower="0.52" upper="3.14" effort="5.0" velocity="1.57" />
  <!-- <dynamics damping="0.5" friction="1.0"/> -->
</joint>

<joint name="joint_5_fixed" type="fixed">
  <origin xyz="0.02 0.025 -0.045" rpy="0 -1.57 0"/>
  <parent link="Link4_1"/>
  <child link="Link5_1"/>
</joint>

<!-- gripper -->

<joint name="joint_5" type="revolute">
  <origin xyz="0 0 0" rpy="1.57 0.7 -1.57"/>
  <parent link="Link5_1"/>
  <child link="grip_base_link"/>
  <axis xyz="0 0 1"/>
  <limit lower="0.52" upper="2.26" effort="5.0" velocity="1.57" />
</joint>

<link
    name="grip_base_link">
    <inertial>
      <origin
        xyz="-0.020531 -0.021072 0.02563"
        rpy="0 0 0" />
      <mass
        value="0.00367" />
      <inertia
        ixx="5.4785E-06"
        ixy="-5.5445E-08"
        ixz="-8.0352E-09"
        iyy="7.0866E-06"
        iyz="-7.7291E-13"
        izz="9.4579E-06" />
    </inertial>
    <visual>
      <origin
        xyz="0 0 0"
        rpy="0 0 0" />
      <geometry>
        <mesh
          filename="package://my_arm_description/meshes/gripper_meshes/grip_base_link.STL" />
      </geometry>
      <material
        name="">
        <color
          rgba="0.89804 0.92157 0.92941 1" />
      </material>
    </visual>
    <collision>
      <origin
        xyz="0 0 0"
        rpy="0 0 0" />
      <geometry>
        <mesh
          filename="package://my_arm_description/meshes/gripper_meshes/grip_base_link.STL" />
      </geometry>
    </collision>
  </link>
  <link
    name="hand_link1">
    <inertial>
      <origin
        xyz="-0.00523492547000686 0.00492501926066897 -0.00100000000000003"
        rpy="0 0 0" />
      <mass
        value="0.000142065726893586" />
      <inertia
        ixx="1.22964066308207E-07"
        ixy="8.46203793647206E-08"
        ixz="3.23650142493458E-27"
        iyy="1.33298297071557E-07"
        iyz="-7.87479068447034E-25"
        izz="2.55315258533807E-07" />
    </inertial>
    <visual>
      <origin
        xyz="0 0 0"
        rpy="0 0 0" />
      <geometry>
        <mesh
          filename="package://my_arm_description/meshes/gripper_meshes/hand_link1.STL" />
      </geometry>
      <material
        name="">
        <color
          rgba="0.898039215686275 0.92156862745098 0.929411764705882 1" />
      </material>
    </visual>
    <collision>
      <origin
        xyz="0 0 0"
        rpy="0 0 0" />
      <geometry>
        <mesh
          filename="package://my_arm_description/meshes/gripper_meshes/hand_link1.STL" />
      </geometry>
    </collision>
  </link>
  <joint
    name="hand_joint1"
    type="revolute">
    <origin
      xyz="0.015 0.00535 0.02625"
      rpy="1.5708 0 3.1416" />
    <parent
      link="grip_base_link" />
    <child
      link="hand_link1" />
    <axis
      xyz="0 0 1" />
    <limit
      lower="-0.5"
      upper="0.5"
      effort="5.0"
      velocity="1.57" />
    <mimic joint="gripper_joint" multiplier="1" />
  </joint>
  <link
    name="hand_grip1">
    <inertial>
      <origin
        xyz="0.00594567238082101 0.0203210851839823 -0.00399999969237515"
        rpy="0 0 0" />
      <mass
        value="0.000187045062582082" />
      <inertia
        ixx="4.0782602368236E-07"
        ixy="-7.95845983485053E-08"
        ixz="-1.31395403259131E-14"
        iyy="3.53476941089525E-08"
        iyz="-2.03499073074993E-14"
        izz="4.38185846898205E-07" />
    </inertial>
    <visual>
      <origin
        xyz="0 0 0"
        rpy="0 0 0" />
      <geometry>
        <mesh
          filename="package://my_arm_description/meshes/gripper_meshes/hand_grip1.STL" />
      </geometry>
      <material
        name="">
        <color
          rgba="0.898039215686275 0.92156862745098 0.929411764705882 1" />
      </material>
    </visual>
    <collision>
      <origin
        xyz="0 0 0"
        rpy="0 0 0" />
      <geometry>
        <mesh
          filename="package://my_arm_description/meshes/gripper_meshes/hand_grip1.STL" />
      </geometry>
    </collision>
  </link>
  <joint
    name="hand_grip_joint1"
    type="revolute">
    <origin
      xyz="-0.021122 0.019871 0"
      rpy="0 0 0" />
    <parent
      link="hand_link1" />
    <child
      link="hand_grip1" />
    <axis
      xyz="0 0 1" />
    <limit
      lower="-0.5"
      upper="0.5"
      effort="5.0"
      velocity="1.57" />
    <mimic joint="hand_joint1" multiplier="-1" />
  </joint>
  <link
    name="hand_link2">
    <inertial>
      <origin
        xyz="0.00521580581542747 0.00494526329837284 -0.00100000000000003"
        rpy="0 0 0" />
      <mass
        value="0.000142065726893586" />
      <inertia
        ixx="1.2361988419095E-07"
        ixy="-8.46578754757815E-08"
        ixz="6.873768146667E-25"
        iyy="1.32642479188815E-07"
        iyz="7.7917326290555E-25"
        izz="2.55315258533807E-07" />
    </inertial>
    <visual>
      <origin
        xyz="0 0 0"
        rpy="0 0 0" />
      <geometry>
        <mesh
          filename="package://my_arm_description/meshes/gripper_meshes/hand_link2.STL" />
      </geometry>
      <material
        name="">
        <color
          rgba="0.898039215686275 0.92156862745098 0.929411764705882 1" />
      </material>
    </visual>
    <collision>
      <origin
        xyz="0 0 0"
        rpy="0 0 0" />
      <geometry>
        <mesh
          filename="package://my_arm_description/meshes/gripper_meshes/hand_link2.STL" />
      </geometry>
    </collision>
  </link>
  <joint
    name="gripper_joint"
    type="revolute">
    <origin
      xyz="-0.013 0.00535 0.02625"
      rpy="1.5708 0 3.1416" />
    <parent
      link="grip_base_link" />
    <child
      link="hand_link2" />
    <axis
      xyz="0 0 -1" />
    <limit
      lower="-0.5"
      upper="0.5"
      effort="5.0"
      velocity="1.57" />
  </joint>
  <link
    name="hand_grip2">
    <inertial>
      <origin
        xyz="-0.00445045993813949 0.020700021082788 -0.00400000030762493"
        rpy="0 0 0" />
      <mass
        value="0.000187045056346137" />
      <inertia
        ixx="4.17408949625888E-07"
        ixy="5.16953875644496E-08"
        ixz="-1.17218822252589E-14"
        iyy="2.57647082341614E-08"
        iyz="2.12711331247855E-14"
        izz="4.38185787066717E-07" />
    </inertial>
    <visual>
      <origin
        xyz="0 0 0"
        rpy="0 0 0" />
      <geometry>
        <mesh
          filename="package://my_arm_description/meshes/gripper_meshes/hand_grip2.STL" />
      </geometry>
      <material
        name="">
        <color
          rgba="0.898039215686275 0.92156862745098 0.929411764705882 1" />
      </material>
    </visual>
    <collision>
      <origin
        xyz="0 0 0"
        rpy="0 0 0" />
      <geometry>
        <mesh
          filename="package://my_arm_description/meshes/gripper_meshes/hand_grip2.STL" />
      </geometry>
    </collision>
  </link>
  <joint
    name="hand_grip_joint2"
    type="revolute">
    <origin
      xyz="0.021045 0.019953 0"
      rpy="0 0 0" />
    <parent
      link="hand_link2" />
    <child
      link="hand_grip2" />
    <axis
      xyz="0 0 -1" />
    <limit
      lower="-0.4"
      upper="0.4"
      effort="5.0"
      velocity="1.57" />
    <mimic joint="gripper_joint" multiplier="-1" />
  </joint>
  <link
    name="mid_link1">
    <inertial>
      <origin
        xyz="-0.0113240288488907 0.00983698991711786 -0.00100000000000003"
        rpy="0 0 0" />
      <mass
        value="0.0000310995574287565" />
      <inertia
        ixx="1.1783554463848E-08"
        ixy="1.26737094661928E-08"
        ixz="7.03369446242362E-26"
        iyy="1.53636899711256E-08"
        iyz="3.46383537128379E-26"
        izz="2.69399140521153E-08" />
    </inertial>
    <visual>
      <origin
        xyz="0 0 0"
        rpy="0 0 0" />
      <geometry>
        <mesh
          filename="package://my_arm_description/meshes/gripper_meshes/mid_link1.STL" />
      </geometry>
      <material
        name="">
        <color
          rgba="0.898039215686275 0.92156862745098 0.929411764705882 1" />
      </material>
    </visual>
    <collision>
      <origin
        xyz="0 0 0"
        rpy="0 0 0" />
      <geometry>
        <mesh
          filename="package://my_arm_description/meshes/gripper_meshes/mid_link1.STL" />
      </geometry>
    </collision>
  </link>
  <joint
    name="mid_joint_1"
    type="revolute">
    <origin
      xyz="0.005 0.00535 0.04675"
      rpy="1.5708 0 3.1416" />
    <parent
      link="grip_base_link" />
    <child
      link="mid_link1" />
    <axis
      xyz="0 0 -1" />
    <limit
      lower="-0.6"
      upper="0.6"
      effort="5.0"
      velocity="1.57" />
    <mimic joint="gripper_joint" multiplier="-1" />
  </joint>
  <link
    name="mid_link2">
    <inertial>
      <origin
        xyz="0 0 0"
        rpy="0 0 0" />
      <mass
        value="0.00003" />
      <inertia
        ixx="0"
        ixy="0"
        ixz="0"
        iyy="0"
        iyz="0"
        izz="0" />
    </inertial>
    <visual>
      <origin
        xyz="0 0 0"
        rpy="0 0 0" />
      <geometry>
        <mesh
          filename="package://my_arm_description/meshes/gripper_meshes/mid_link2.STL" />
      </geometry>
      <material
        name="">
        <color
          rgba="1 1 1 1" />
      </material>
    </visual>
    <collision>
      <origin
        xyz="0 0 0"
        rpy="0 0 0" />
      <geometry>
        <mesh
          filename="package://my_arm_description/meshes/gripper_meshes/mid_link2.STL" />
      </geometry>
    </collision>
  </link>
  <joint
    name="mid_joint_2"
    type="revolute">
    <origin
      xyz="-0.005 0.00535 0.04675"
      rpy="1.5708 0 3.1416" />
    <parent
      link="grip_base_link" />
    <child
      link="mid_link2" />
    <axis
      xyz="0 0 -1" />
    <limit
      lower="-0.6"
      upper="0.6"
      effort="5.0"
      velocity="1.57" />
    <mimic joint="gripper_joint" multiplier="1" />
  </joint>

  <!-- TCP -->

  <link name="tool_link" />

  <joint name="tool_joint" type="fixed">
    <origin xyz="0 0 0.1" rpy="0 0 0"/>
    <parent link="grip_base_link"/>
    <child link="tool_link"/>
  </joint>

</robot>
