<?xml version="1.0" ?>
<!-- =================================================================================== -->
<!-- |    This document was autogenerated by xacro from robot_arm.xacro                | -->
<!-- |    EDITING THIS FILE BY HAND IS NOT RECOMMENDED                                 | -->
<!-- =================================================================================== -->
<robot name="robot_arm">
  <link name="world"/>
  <joint name="base_fixed_joint" type="fixed">
    <parent link="world"/>
    <child link="base_link"/>
    <origin rpy="0 0 0" xyz="0 0 0.2"/>
  </joint>
  <link name="base_link">
    <inertial>
      <origin rpy="0 0 0" xyz="-0.0019226671084236508 0.03127199959893212 0.003074002176362074"/>
      <mass value="0.1"/>
      <inertia ixx="0.0135" ixy="0.0" ixz="0.0" iyy="0.0135" iyz="0.0" izz="0.05"/>
    </inertial>
    <visual>
      <origin rpy="1.57 0 0" xyz="0 0 0"/>
      <geometry>
        <mesh filename="package://my_arm_description/meshes/base_link.stl" scale="0.001 0.001 0.001"/>
      </geometry>
      <material name="blue"/>
    </visual>
    <collision>
      <origin rpy="1.57 0 0" xyz="0 0 0"/>
      <geometry>
        <mesh filename="package://my_arm_description/meshes/base_link.stl" scale="0.001 0.001 0.001"/>
      </geometry>
    </collision>
  </link>
  <link name="Link1_1">
    <inertial>
      <origin rpy="0 0 0" xyz="-4.991869489348773e-06 0.01780900870871517 0.005735315172792203"/>
      <mass value="0.08948947756149551"/>
      <inertia ixx="0.000574" ixy="-1.2e-05" ixz="-2e-05" iyy="0.002344" iyz="-7.9e-05" izz="0.002106"/>
    </inertial>
    <visual>
      <origin rpy="0 0 0" xyz="0.002688 -0.06295 -0.001684"/>
      <geometry>
        <mesh filename="package://my_arm_description/meshes/Link1_1.stl" scale="0.001 0.001 0.001"/>
      </geometry>
      <material name="silver"/>
    </visual>
    <collision>
      <origin rpy="0 0 0" xyz="0.002688 -0.06295 -0.001684"/>
      <geometry>
        <mesh filename="package://my_arm_description/meshes/Link1_1.stl" scale="0.001 0.001 0.001"/>
      </geometry>
    </collision>
  </link>
  <link name="Link2_1">
    <inertial>
      <origin rpy="0 0 0" xyz="0.025500212363618904 0.050000197846483144 2.9486110807164234e-07"/>
      <mass value="0.01268747558623512"/>
      <inertia ixx="0.000111" ixy="0.0" ixz="-0.0" iyy="7.8e-05" iyz="-0.0" izz="0.000176"/>
    </inertial>
    <visual>
      <origin rpy="0 0 0" xyz="0.028738 -0.084331 -0.001684"/>
      <geometry>
        <mesh filename="package://my_arm_description/meshes/Link2_1.stl" scale="0.001 0.001 0.001"/>
      </geometry>
      <material name="silver"/>
    </visual>
    <collision>
      <origin rpy="0 0 0" xyz="0.028738 -0.084331 -0.001684"/>
      <geometry>
        <mesh filename="package://my_arm_description/meshes/Link2_1.stl" scale="0.001 0.001 0.001"/>
      </geometry>
    </collision>
  </link>
  <link name="Link3_1">
    <inertial>
      <origin rpy="0 0 0" xyz="0.027076002474259824 0.019409440802769573 0.002368883434935072"/>
      <mass value="0.03877413615001566"/>
      <inertia ixx="0.00025" ixy="1e-05" ixz="0.0" iyy="0.000103" iyz="-7e-06" izz="0.00031"/>
    </inertial>
    <visual>
      <origin rpy="0 0 0" xyz="0.028738 -0.184331 -0.001684"/>
      <geometry>
        <mesh filename="package://my_arm_description/meshes/Link3_1.stl" scale="0.001 0.001 0.001"/>
      </geometry>
      <material name="silver"/>
    </visual>
    <collision>
      <origin rpy="0 0 0" xyz="0.028738 -0.184331 -0.001684"/>
      <geometry>
        <mesh filename="package://my_arm_description/meshes/Link3_1.stl" scale="0.001 0.001 0.001"/>
      </geometry>
    </collision>
  </link>
  <link name="Link4_1">
    <inertial>
      <origin rpy="0 0 0" xyz="0.02792782389157162 0.0015768795382742895 -0.009656526599892783"/>
      <mass value="0.030477625056794005"/>
      <inertia ixx="6.9e-05" ixy="-1e-06" ixz="2e-06" iyy="9.7e-05" iyz="0.0" izz="5.9e-05"/>
    </inertial>
    <visual>
      <origin rpy="0 0 0" xyz="0.030288 -0.27563 -0.005184"/>
      <geometry>
        <mesh filename="package://my_arm_description/meshes/Link4_1.stl" scale="0.001 0.001 0.001"/>
      </geometry>
      <material name="silver"/>
    </visual>
    <collision>
      <origin rpy="0 0 0" xyz="0.030288 -0.27563 -0.005184"/>
      <geometry>
        <mesh filename="package://my_arm_description/meshes/Link4_1.stl" scale="0.001 0.001 0.001"/>
      </geometry>
    </collision>
  </link>
  <link name="Link5_1">
    <inertial>
      <origin rpy="0 0 0" xyz="0.02792782389157162 0.0015768795382742895 -0.009656526599892783"/>
      <mass value="0.030477625056794005"/>
      <inertia ixx="6.9e-05" ixy="-1e-06" ixz="2e-06" iyy="9.7e-05" iyz="0.0" izz="5.9e-05"/>
    </inertial>
    <visual>
      <origin rpy="0 0 0" xyz="0.030288 -0.27563 -0.005184"/>
      <geometry>
        <mesh filename="package://my_arm_description/meshes/Link4_1.stl" scale="0.001 0.001 0.001"/>
      </geometry>
      <material name="silver"/>
    </visual>
    <collision>
      <origin rpy="0 0 0" xyz="0.030288 -0.27563 -0.005184"/>
      <geometry>
        <mesh filename="package://my_arm_description/meshes/Link4_1.stl" scale="0.001 0.001 0.001"/>
      </geometry>
    </collision>
  </link>
  <joint name="joint_1" type="revolute">
    <origin rpy="1.57 0 0" xyz="0 0 0.06"/>
    <parent link="base_link"/>
    <child link="Link1_1"/>
    <axis xyz="0 1 0"/>
    <limit effort="5.0" lower="-3.14" upper="3.14" velocity="1.57"/>
  </joint>
  <joint name="joint_2" type="revolute">
    <origin rpy="0 0 0" xyz="-0.02605 0.021381 0.0"/>
    <parent link="Link1_1"/>
    <child link="Link2_1"/>
    <axis xyz="-1 0 0"/>
    <limit effort="5.0" lower="-1.57" upper="1.57" velocity="1.57"/>
  </joint>
  <joint name="joint_3" type="revolute">
    <origin rpy="0 0 0" xyz="0.0 0.1 0.0"/>
    <parent link="Link2_1"/>
    <child link="Link3_1"/>
    <axis xyz="-1 0 0"/>
    <limit effort="5.0" lower="-2.2" upper="2.2" velocity="1.57"/>
  </joint>
  <joint name="joint_4" type="revolute">
    <origin rpy="0 0 0" xyz="-0.00155 0.091299 0.0035"/>
    <parent link="Link3_1"/>
    <child link="Link4_1"/>
    <axis xyz="-1 0 0"/>
    <limit effort="5.0" lower="-3.14" upper="1.2" velocity="1.57"/>
  </joint>
  <joint name="joint_5_fixed" type="fixed">
    <origin rpy="0 -1.57 0" xyz="0.02 0.025 -0.045"/>
    <parent link="Link4_1"/>
    <child link="Link5_1"/>
  </joint>
  
  <!-- gripper -->
  <joint name="joint_5" type="revolute">
    <origin rpy="1.57 0 -1.57" xyz="0 0 0"/>
    <parent link="Link5_1"/>
    <child link="grip_base_link"/>
    <axis xyz="0 0 1"/>
    <limit effort="5.0" lower="-3.14" upper="3.14" velocity="1.57"/>
  </joint>
  <link name="grip_base_link">
    <inertial>
      <origin rpy="0 0 0" xyz="-0.020531 -0.021072 0.02563"/>
      <mass value="0.00367"/>
      <inertia ixx="5.4785E-06" ixy="-5.5445E-08" ixz="-8.0352E-09" iyy="7.0866E-06" iyz="-7.7291E-13" izz="9.4579E-06"/>
    </inertial>
    <visual>
      <origin rpy="0 0 0" xyz="0 0 0"/>
      <geometry>
        <mesh filename="package://my_arm_description/meshes/gripper_meshes/grip_base_link.STL"/>
      </geometry>
      <material name="">
        <color rgba="0.89804 0.92157 0.92941 1"/>
      </material>
    </visual>
    <collision>
      <origin rpy="0 0 0" xyz="0 0 0"/>
      <geometry>
        <mesh filename="package://my_arm_description/meshes/gripper_meshes/grip_base_link.STL"/>
      </geometry>
    </collision>
  </link>
  
  <!-- TCP -->
  <link name="tool_link"/>
  <joint name="tool_joint" type="fixed">
    <origin rpy="0 0 0" xyz="0 0 0.1"/>
    <parent link="grip_base_link"/>
    <child link="tool_link"/>
  </joint>
</robot>
